Workbook
Name CfgLoc: Configs!$D$6:$D$25
Name CfgMix: Configs!$G$6:$G$25
Name CfgName: Configs!$C$6:$C$25
Name CfgProp: Configs!$E$6:$E$25
Name CfgRoast: Configs!$F$6:$F$25
Name Circ: Cover!$D$29
Name Lakh: Inputs!$D$27
Name LocList: Locations!$D$5:$G$5
Name MixCheck: Sourcing!$F$20:$I$20
Name MixList: Sourcing!$F$14:$I$14
Name PropList: Inputs!$F$167:$H$167
Name RoastList: Sourcing!$F$41:$H$41
Name ScnList: Inputs!$F$168:$I$168
Name TaxRate: Inputs!$D$28

Sheet Cover
B1: Specialty Café, Ahmedabad: 3-Statement & FCFF DCF Model
B2: Location × premises (rent/own) × roasting × bean-mix decision model. Prepared October 2026. All figures in ₹ lakh unless stated (1 lakh = ₹1,00,000).
B3: ="Model running: "&Inputs!$D$23 -> Model running: Prahladnagar | Rent | Toll roasting | Specialty mix | Base case
B5: Contents
B6: Dashboard | C6: Key outputs, charts, scenario and premises comparison
B7: Inputs | C7: Configuration switches, Best/Base/Worst drivers, all operating assumptions
B8: Locations | C8: Library of four Ahmedabad sites: rent, area, footfall, ticket, capex
B9: Sourcing | C9: Green-coffee prices, bean mixes, cost per kg by roasting route
B10: Capex | C10: Equipment & fit-out list, property purchase, sources & uses of funds
B11: Model | C11: Income statement, cash flow, balance sheet and supporting schedules
B12: DCF | C12: FCFF, WACC, terminal value, NPV, IRR, equity IRR, payback
B13: Scenarios | C13: Override panel and live data tables (scenarios, sensitivities, tornado)
B14: Configs | C14: 19 pre-defined configurations compared side by side (editable)
B15: Sources | C15: Where the assumptions come from
B17: Model checks
B18: Balance sheet balances (all years) | D18: =IF(SUMPRODUCT(ABS(Model!$F$76:$P$76))<0.01,"OK","ERROR") -> OK
B19: Cash never negative | D19: =IF(MIN(Model!$F$61:$P$61)>=-0.001,"OK","ERROR") -> OK
B20: Sources of funds = uses of funds | D20: =IF(ABS(Capex!$G$53-Capex!$G$58)<0.001,"OK","ERROR") -> OK
B21: Every bean mix adds up to 100% | D21: =IF(SUMPRODUCT(ABS(MixCheck-1))<0.0001,"OK","ERROR") -> OK
B22: Revenue mix shares between 0% and 100% | D22: =IF(AND(Inputs!$D$77>=0,Inputs!$D$77<=1),"OK","ERROR") -> OK
B23: WACC above terminal growth | D23: =IF(DCF!$D$41>DCF!$D$42,"OK","ERROR") -> OK
B24: Seating capacity does not cap demand | D24: =IF(SUMPRODUCT(--(Model!$F$83:$P$83>Model!$F$84:$P$84+0.001))=0,"OK","INFO: capacity binds") -> OK
B25: Scenarios-sheet overrides switched off | D25: =IF(AND(Scenarios!$D$6=0,Scenarios!$D$7=0,Scenarios!$D$8=0,Scenarios!$D$9=0,Scenarios!$D$10=0,Scenarios!$D$11=0,Scenarios!$D$13=1,Scenarios!$D$14=1,Scenarios!$D$15=1,Scenarios!$D$16=1,Scenarios!$D$17=1,Scenarios!$D$18=1,Scenarios!$D$19=0,Scenarios!$D$20=0,Scenarios!$D$21=0,Scenarios!$D$22=0,Scenarios!$D$12=0),"OK","INFO: overrides active") -> OK
B26: Overall model status | D26: =IF(COUNTIF(D18:D23,"OK")=6,"ALL CHECKS OK","REVIEW") -> ALL CHECKS OK
B28: Switches
B29: Circularity switch (1 = interest on average balances) | C29: 0 = interest on opening balances (no circular reference). 1 needs iterative calculation (enabled in this file). | D29: 0
B31: Conventions
B32: Blue on cream | C32: Hard-coded input: change these
B33: Black | C33: Formula on the same sheet
B34: Green | C34: Formula linking to another sheet
B35: Units | C35: ₹ lakh unless the Units column says otherwise; rupee inputs are in ₹
B36: Timeline | C36: Y0 = FY27 (fit-out, pre-opening; ends 31 Mar 2027). Y1-Y10 = FY28-FY37. Annual periods, fiscal year to 31 March
B37: Signs | C37: Income statement costs and cash outflows are shown as negatives
B38: Tax | C38: Corporate tax under s.115BAA, 25.168% incl. surcharge & cess; WDV tax depreciation; losses carried forward
B39: Leases | C39: Rent is an operating expense (Indian GAAP / AS for an unlisted SME, no Ind AS 116 right-of-use asset)
B41: How to use
B42: 1. Inputs sheet, section 1: pick Location, Premises (Rent / Own), Roasting route, Bean mix and Scenario from the drop-downs.
B43: 2. Read the result on the Dashboard; every statement and schedule is on the Model and DCF sheets.
B44: 3. Change any blue cell (Inputs, Locations, Sourcing, Capex, Configs) to test your own numbers.
B45: 4. Scenarios sheet: live data tables re-run the whole model for every scenario, configuration and sensitivity. Leave its override cells at their defaults.
...

Sheet Dashboard
B1: Dashboard
B2: Outputs for the configuration and scenario chosen on Inputs. ₹ lakh unless stated.
B3: ="Model running: "&Inputs!$D$23 -> Model running: Prahladnagar | Rent | Toll roasting | Specialty mix | Base case
B5: Selected configuration
B6: Location | D6: =Inputs!$F$15 -> Prahladnagar
B7: Premises | D7: =Inputs!$F$16 -> Rent
B8: Roasting route | D8: =Inputs!$F$17 -> Toll roasting
B9: Bean mix | D9: =Inputs!$F$18 -> Specialty
B10: Scenario | D10: =Inputs!$F$19 -> Base
B12: Key outputs
B13: Total capital requirement | D13: =DCF!$D$80 -> 101.228 | F13: Payback from opening | J13: =DCF!$D$76 -> 4.7237112
B14: Promoter equity | D14: =DCF!$D$81 -> 68.028 | F14: Discounted payback | J14: =DCF!$D$77 -> 8.1954564
B15: Term loan | D15: =DCF!$D$82 -> 33.2 | F15: Revenue Y3 | J15: =DCF!$D$84 -> 177.8112
B16: WACC | D16: =DCF!$D$41 -> 0.161554 | F16: EBITDA Y3 | J16: =DCF!$D$85 -> 33.683883
B17: Cost of equity | D17: =DCF!$D$37 -> 0.20022526 | F17: EBITDA margin Y3 | J17: =DCF!$D$86 -> 0.18943623
B18: Project NPV | D18: =DCF!$D$61 -> 89.598107 | F18: Bills per day Y3 | J18: =DCF!$D$88 -> 140
B19: Project IRR | D19: =DCF!$D$64 -> 0.28636431 | F19: Break-even bills per day Y3 | J19: =DCF!$D$89 -> 95.968282
B20: Equity IRR | D20: =DCF!$D$68 -> 0.3293081 | F20: Margin of safety Y3 | J20: =DCF!$D$90 -> 0.31451227
B21: Equity NPV at cost of equity | D21: =DCF!$D$69 -> 65.839478 | F21: Peak cash-credit draw | J21: =DCF!$D$97 -> 0
B22: Equity multiple | D22: =DCF!$D$70 -> 8.8873609 | F22: Minimum DSCR (Y2 on) | J22: =DCF!$D$98 -> 1.851354
B23: Terminal value share of value | D23: =DCF!$D$62 -> 0.42342231 | F23: Pre-tax ROCE Y5 | J23: =DCF!$D$101 -> 0.73062017
B24: Implied exit EV/EBITDA | D24: =DCF!$D$56 -> 5.5955523 | F24: Cash lost if shut after Y3 | J24: =DCF!$D$99 -> 19.628082
B26: Financial summary (₹ lakh)
B27: ₹ lakh | F27: =Model!F5 -> 2027 | G27: =Model!G5 -> 2028 | H27: =Model!H5 -> 2029 | I27: =Model!I5 -> 2030 | J27: =Model!J5 -> 2031 | K27: =Model!K5 -> 2032 | L27: =Model!L5 -> 2033 | M27: =Model!M5 -> 2034 | ... P27: =Model!P5 -> 2037
B28: Bills per day | C28: # | F28: =Model!F85 -> 0 | G28: =Model!G85 -> 91 | H28: =Model!H85 -> 119 | I28: =Model!I85 -> 140 | J28: =Model!J85 -> 143.5 | K28: =Model!K85 -> 147.0875 | L28: =Model!L85 -> 150.76469 | M28: =Model!M85 -> 154.5338 | ... P28: =Model!P85 -> 166.41601
B29: Average bill (₹) | C29: ₹ | F29: =Model!F89 -> 0 | G29: =Model!G89 -> 320 | H29: =Model!H89 -> 336 | I29: =Model!I89 -> 352.8 | J29: =Model!J89 -> 370.44 | K29: =Model!K89 -> 388.962 | L29: =Model!L89 -> 408.4101 | M29: =Model!M89 -> 428.83061 | ... P29: =Model!P89 -> 496.42503
B30: Revenue | C30: ₹ lakh | F30: =Model!F16 -> 0 | G30: =Model!G16 -> 104.832 | H30: =Model!H16 -> 143.9424 | I30: =Model!I16 -> 177.8112 | J30: =Model!J16 -> 191.3693 | K30: =Model!K16 -> 205.96121 | L30: =Model!L16 -> 221.66576 | M30: =Model!M16 -> 238.56777 | ... P30: =Model!P16 -> 297.40705
B31: Gross margin | C31: % | F31: =Model!F20 -> 0 | G31: =Model!G20 -> 0.69758569 | H31: =Model!H20 -> 0.69919187 | I31: =Model!I20 -> 0.70076745 | J31: =Model!J20 -> 0.70231499 | K31: =Model!K20 -> 0.70382976 | L31: =Model!L20 -> 0.70531469 | M31: =Model!M20 -> 0.70677233 | ... P31: =Model!P20 -> 0.71098601
B32: EBITDA | C32: ₹ lakh | F32: =Model!F29 -> -11.0545 | G32: =Model!G29 -> -3.722047 | H32: =Model!H29 -> 17.701906 | I32: =Model!I29 -> 33.683883 | J32: =Model!J29 -> 36.555685 | K32: =Model!K29 -> 39.61794 | L32: =Model!L29 -> 42.879726 | M32: =Model!M29 -> 46.350071 | ... P32: =Model!P29 -> 58.095121
B33: EBITDA margin | C33: % | F33: =Model!F30 -> 0 | G33: =Model!G30 -> -0.035504875 | H33: =Model!H30 -> 0.1229791 | I33: =Model!I30 -> 0.18943623 | J33: =Model!J30 -> 0.19102168 | K33: =Model!K30 -> 0.19235632 | L33: =Model!L30 -> 0.19344317 | M33: =Model!M30 -> 0.19428471 | ... P33: =Model!P30 -> 0.19533875
B34: Profit after tax | C34: ₹ lakh | F34: =Model!F38 -> -11.0545 | G34: =Model!G38 -> -14.924471 | H34: =Model!H38 -> 6.6158733 | I34: =Model!I38 -> 22.001296 | J34: =Model!J38 -> 20.077347 | K34: =Model!K38 -> 23.411655 | L34: =Model!L38 -> 26.600993 | M34: =Model!M38 -> 27.84088 | ... P34: =Model!P38 -> 45.306616
B35: Cash from operations | C35: ₹ lakh | F35: =Model!F46 -> -11.0545 | G35: =Model!G46 -> -7.8165266 | H35: =Model!H46 -> 14.469085 | I35: =Model!I46 -> 30.057111 | J35: =Model!J46 -> 28.627479 | K35: =Model!K46 -> 31.921775 | L35: =Model!L46 -> 35.699186 | M35: =Model!M46 -> 39.034682 | ... P35: =Model!P46 -> 51.050829
B36: Capex | C36: ₹ lakh | F36: =Model!F47 -> -66.465 | G36: =Model!G47 -> -1.57248 | H36: =Model!H47 -> -2.159136 | I36: =Model!I47 -> -2.667168 | J36: =Model!J47 -> -2.8705396 | K36: =Model!K47 -> -3.0894182 | L36: =Model!L47 -> -14.816306 | M36: =Model!M47 -> -3.5785165 | ... P36: =Model!P47 -> -4.4611058
B37: Free cash flow to firm | C37: ₹ lakh | F37: =DCF!F24 -> -82.1195 | G37: =DCF!G24 -> -6.5013466 | H37: =DCF!H24 -> 15.108369 | I37: =DCF!I24 -> 27.336694 | J37: =DCF!J24 -> 25.967086 | K37: =DCF!K24 -> 27.923707 | L37: =DCF!L24 -> 18.763378 | M37: =DCF!M24 -> 32.71158 | ... P37: =DCF!P24 -> 40.344655
B38: Cumulative FCFF | C38: ₹ lakh | F38: =DCF!F72 -> -82.1195 | G38: =DCF!G72 -> -88.620847 | H38: =DCF!H72 -> -73.512477 | I38: =DCF!I72 -> -46.175784 | J38: =DCF!J72 -> -20.208698 | K38: =DCF!K72 -> 7.7150088 | L38: =DCF!L72 -> 26.478386 | M38: =DCF!M72 -> 59.189967 | ... P38: =DCF!P72 -> 172.24732
B39: Closing cash | C39: ₹ lakh | F39: =Model!F61 -> 19.1085 | G39: =Model!G61 -> 3.0794934 | H39: =Model!H61 -> 8.7494423 | I39: =Model!I61 -> 29.499385 | J39: =Model!J61 -> 48.616324 | K39: =Model!K61 -> 70.808681 | L39: =Model!L61 -> 91.691561 | M39: =Model!M61 -> 127.14773 | ... P39: =Model!P61 -> 255.22602
B40: Debt (term loan + cash credit) | C40: ₹ lakh | F40: =Model!F203+Model!F209 -> 33.2 | G40: =Model!G203+Model!G209 -> 26.56 | H40: =Model!H203+Model!H209 -> 19.92 | I40: =Model!I203+Model!I209 -> 13.28 | J40: =Model!J203+Model!J209 -> 6.64 | K40: =Model!K203+Model!K209 -> 0 | L40: =Model!L203+Model!L209 -> 0 | M40: =Model!M203+Model!M209 -> 0 | ... P40: =Model!P203+Model!P209 -> 0
B41: Shareholders' equity | C41: ₹ lakh | F41: =Model!F74 -> 56.9735 | G41: =Model!G74 -> 42.049029 | H41: =Model!H74 -> 48.664903 | I41: =Model!I74 -> 70.666199 | J41: =Model!J74 -> 90.743546 | K41: =Model!K74 -> 114.1552 | L41: =Model!L74 -> 140.75619 | M41: =Model!M74 -> 168.59707 | ... P41: =Model!P74 -> 284.20371
B43: Scenario analysis (from Scenarios T1)
B44: Scenario | F44: NPV | G44: Project IRR | H44: Equity IRR | I44: Payback | J44: Y3 revenue | K44: Y3 EBITDA % | L44: Break-even bills | M44: Capital need
...

Sheet Inputs
B1: Inputs & Drivers
B2: Blue cells are inputs. Rupee inputs in ₹ (not lakh). Driver rows marked Live are picked by the Scenario switch.
B3: ="Model running: "&$D$23 -> Model running: Prahladnagar | Rent | Toll roasting | Specialty mix | Base case
B5: ₹ lakh unless stated | C5: Units | D5: Value | F5: =$D$26 -> 2027 | G5: =F5+1 -> 2028 | H5: =G5+1 -> 2029 | I5: =H5+1 -> 2030 | J5: =I5+1 -> 2031 | K5: =J5+1 -> 2032 | L5: =K5+1 -> 2033 | M5: =L5+1 -> 2034 | N5: =M5+1 -> 2035 | ... P5: =O5+1 -> 2037
B6: Period (Y0 = pre-opening fit-out year) | F6: =F5-$D$26 -> 0 | G6: =G5-$D$26 -> 1 | H6: =H5-$D$26 -> 2 | I6: =I5-$D$26 -> 3 | J6: =J5-$D$26 -> 4 | K6: =K5-$D$26 -> 5 | L6: =L5-$D$26 -> 6 | M6: =M5-$D$26 -> 7 | ... P6: =P5-$D$26 -> 10
B7: 1. Configuration: choose what to model
B8: Location | C8: list | D8: Prahladnagar | F8: Prahladnagar (base case), Sindhu Bhavan Road, GIFT City, Sanand: see Locations
B9: Premises | C9: list | D9: Rent | F9: Rent a unit, or buy it (60% funded by a loan against property)
B10: Coffee roasting route | C10: list | D10: Toll roasting | F10: Buy roasted beans / toll-roast your own green coffee / own 3 kg roaster
B11: Bean mix | C11: list | D11: Specialty | F11: Value / Specialty / Premium / Custom blends: see Sourcing
B12: Scenario | C12: list | D12: Base | F12: Best / Base / Worst drivers below
B14: Active configuration (after any Scenarios-sheet overrides)
B15: Location (index) | C15: # | D15: =IF(Scenarios!$D$8>0,Scenarios!$D$8,IF(Scenarios!$D$7>0,MATCH(INDEX(CfgLoc,Scenarios!$D$7),LocList,0),MATCH($D$8,LocList,0))) -> 1 | F15: =INDEX(LocList,$D$15) -> Prahladnagar
B16: Premises (index) | C16: # | D16: =IF(Scenarios!$D$9>0,Scenarios!$D$9,IF(Scenarios!$D$7>0,MATCH(INDEX(CfgProp,Scenarios!$D$7),PropList,0),MATCH($D$9,PropList,0))) -> 1 | F16: =INDEX(PropList,$D$16) -> Rent
B17: Roasting route (index) | C17: # | D17: =IF(Scenarios!$D$10>0,Scenarios!$D$10,IF(Scenarios!$D$7>0,MATCH(INDEX(CfgRoast,Scenarios!$D$7),RoastList,0),MATCH($D$10,RoastList,0))) -> 2 | F17: =INDEX(RoastList,$D$17) -> Toll roasting
B18: Bean mix (index) | C18: # | D18: =IF(Scenarios!$D$11>0,Scenarios!$D$11,IF(Scenarios!$D$7>0,MATCH(INDEX(CfgMix,Scenarios!$D$7),MixList,0),MATCH($D$11,MixList,0))) -> 2 | F18: =INDEX(MixList,$D$18) -> Specialty
B19: Scenario (index) | C19: # | D19: =IF(Scenarios!$D$6>0,Scenarios!$D$6,MATCH($D$12,ScnList,0)) -> 2 | F19: =INDEX(ScnList,$D$19) -> Base
B20: Owned premises flag | C20: 1/0 | D20: =IF($D$16=2,1,0) -> 0
B21: In-house roastery flag | C21: 1/0 | D21: =IF($D$17=3,1,0) -> 0
B22: Own-label beans flag (toll or in-house) | C22: 1/0 | D22: =IF($D$17>=2,1,0) -> 1
B23: Configuration label | C23: text | D23: =$F$15&" | "&$F$16&" | "&$F$17&" | "&$F$18&" mix | "&$F$19&" case" -> Prahladnagar | Rent | Toll roasting | Specialty mix | Base case
B25: 2. General
B26: Year 0 (fit-out year) ends 31 March | C26: FY | D26: 2027 | F26: Y0 = FY2026-27: lease/purchase, fit-out, hiring. Café opens 1 April 2027 (Y1)
B27: Rupees per lakh | C27: ₹ | D27: 100000
B28: Corporate tax rate (s.115BAA) | C28: % | D28: 0.25168 | F28: 22% + 10% surcharge + 4% cess = 25.168%; no MAT under 115BAA
B30: 3. Scenario drivers: Best / Base / Worst (Live row = selected scenario)
B31: Ramp-up (% of steady-state bills)
B32: Best | C32: % | G32: 0.8 | H32: 0.95 | I32: 1 | J32: 1 | K32: 1 | L32: 1 | M32: 1 | N32: 1 | O32: 1 | P32: 1
B33: Base | C33: % | G33: 0.65 | H33: 0.85 | I33: 1 | J33: 1 | K33: 1 | L33: 1 | M33: 1 | N33: 1 | O33: 1 | P33: 1
B34: Worst | C34: % | G34: 0.5 | H34: 0.7 | I34: 0.88 | J34: 0.95 | K34: 0.95 | L34: 0.95 | M34: 0.95 | N34: 0.95 | O34: 0.95 | P34: 0.95
B35: Live | C35: % | G35: =CHOOSE($D$19,G32,G33,G34) -> 0.65 | H35: =CHOOSE($D$19,H32,H33,H34) -> 0.85 | I35: =CHOOSE($D$19,I32,I33,I34) -> 1 | J35: =CHOOSE($D$19,J32,J33,J34) -> 1 | K35: =CHOOSE($D$19,K32,K33,K34) -> 1 | L35: =CHOOSE($D$19,L32,L33,L34) -> 1 | M35: =CHOOSE($D$19,M32,M33,M34) -> 1 | N35: =CHOOSE($D$19,N32,N33,N34) -> 1 | ... P35: =CHOOSE($D$19,P32,P33,P34) -> 1
B36: Menu price increase
B37: Best | C37: % p.a. | G37: 0 | H37: 0.06 | I37: 0.06 | J37: 0.06 | K37: 0.06 | L37: 0.06 | M37: 0.06 | N37: 0.06 | O37: 0.06 | P37: 0.06
B38: Base | C38: % p.a. | G38: 0 | H38: 0.05 | I38: 0.05 | J38: 0.05 | K38: 0.05 | L38: 0.05 | M38: 0.05 | N38: 0.05 | O38: 0.05 | P38: 0.05
B39: Worst | C39: % p.a. | G39: 0 | H39: 0.035 | I39: 0.035 | J39: 0.035 | K39: 0.035 | L39: 0.035 | M39: 0.035 | N39: 0.035 | O39: 0.035 | P39: 0.035
B40: Live | C40: % p.a. | G40: =CHOOSE($D$19,G37,G38,G39) -> 0 | H40: =CHOOSE($D$19,H37,H38,H39) -> 0.05 | I40: =CHOOSE($D$19,I37,I38,I39) -> 0.05 | J40: =CHOOSE($D$19,J37,J38,J39) -> 0.05 | K40: =CHOOSE($D$19,K37,K38,K39) -> 0.05 | L40: =CHOOSE($D$19,L37,L38,L39) -> 0.05 | M40: =CHOOSE($D$19,M37,M38,M39) -> 0.05 | N40: =CHOOSE($D$19,N37,N38,N39) -> 0.05 | ... P40: =CHOOSE($D$19,P37,P38,P39) -> 0.05
B41: Volume growth after ramp (Y4+)
B42: Best | C42: % p.a. | G42: 0 | H42: 0 | I42: 0 | J42: 0.04 | K42: 0.04 | L42: 0.04 | M42: 0.04 | N42: 0.04 | O42: 0.04 | P42: 0.04
B43: Base | C43: % p.a. | G43: 0 | H43: 0 | I43: 0 | J43: 0.025 | K43: 0.025 | L43: 0.025 | M43: 0.025 | N43: 0.025 | O43: 0.025 | P43: 0.025
B44: Worst | C44: % p.a. | G44: 0 | H44: 0 | I44: 0 | J44: 0.005 | K44: 0.005 | L44: 0.005 | M44: 0.005 | N44: 0.005 | O44: 0.005 | P44: 0.005
...

Sheet Locations
B1: Location library
B2: Four candidate sites. Edit any blue cell; column H feeds the model.
B3: ="Model running: "&Inputs!$D$23 -> Model running: Prahladnagar | Rent | Toll roasting | Specialty mix | Base case
B5: Parameter | C5: Units | D5: Prahladnagar | E5: Sindhu Bhavan Road | F5: GIFT City | G5: Sanand | H5: =INDEX(D5:G5,Inputs!$D$15) -> Prahladnagar | J5: Notes & evidence
B6: Café carpet area | C6: sqft | D6: 1000 | E6: 1200 | F6: 900 | G6: 1000 | H6: =INDEX(D6:G6,Inputs!$D$15) -> 1000 | J6: Ground-floor, street-facing unit; 36-52 seats
B7: Seats | C7: # | D7: 40 | E7: 52 | F7: 36 | G7: 40 | H7: =INDEX(D7:G7,Inputs!$D$15) -> 40 | J7: ~22-25 sqft per seat incl. counter & kitchen
B8: Rent | C8: ₹/sqft/mth | D8: 115 | E8: 175 | F8: 110 | G8: 50 | H8: =INDEX(D8:G8,Inputs!$D$15) -> 115 | J8: Listings Oct 2026: Prahladnagar ₹55-120, SBR ₹85-220 (F&B frontage at top end), GIFT ~₹110, Sanand est.
B9: CAM / maintenance | C9: ₹/sqft/mth | D9: 4 | E9: 5 | F9: 15 | G9: 2 | H9: =INDEX(D9:G9,Inputs!$D$15) -> 4 | J9: Grade-A towers in GIFT charge high CAM
B10: Security deposit | C10: months | D10: 4 | E10: 6 | F10: 6 | G10: 3 | H10: =INDEX(D10:G10,Inputs!$D$15) -> 4 | J10: Refundable; 2-6 months typical
B11: Interiors, civil & MEP | C11: ₹/sqft | D11: 2600 | E11: 3000 | F11: 2600 | G11: 2000 | H11: =INDEX(D11:G11,Inputs!$D$15) -> 2600 | J11: Incl. design fees; excludes equipment
B12: Purchase price (own case) | C12: ₹/sqft | D12: 17500 | E12: 24000 | F12: 14000 | G12: 6500 | H12: =INDEX(D12:G12,Inputs!$D$15) -> 17500 | J12: Ground-floor retail, carpet basis; SBR showrooms listed ₹19.5-21.5k on built-up area
B13: Steady-state bills per day | C13: # | D13: 140 | E13: 170 | F13: 150 | G13: 110 | H13: =INDEX(D13:G13,Inputs!$D$15) -> 140 | J13: Year-3 demand at 100% ramp (Base footfall factor 1.0)
B14: Average bill value (ex-GST, FY28) | C14: ₹ | D14: 320 | E14: 360 | F14: 330 | G14: 260 | H14: =INDEX(D14:G14,Inputs!$D$15) -> 320 | J14: Specialty cafés ₹500-1,500 for two in Ahmedabad listings
B15: Operating days per year | C15: days | D15: 360 | E15: 360 | F15: 290 | G15: 350 | H15: =INDEX(D15:G15,Inputs!$D$15) -> 360 | J15: GIFT City: weekday-heavy demand
B16: Delivery share of café revenue | C16: % | D16: 0.15 | E16: 0.1 | F16: 0.06 | G16: 0.15 | H16: =INDEX(D16:G16,Inputs!$D$15) -> 0.15 | J16: Swiggy/Zomato orders
B17: Extra volume growth, Y2-Y6 | C17: % p.a. | D17: 0 | E17: 0.005 | F17: 0.04 | G17: 0.05 | H17: =INDEX(D17:G17,Inputs!$D$15) -> 0 | J17: GIFT workforce & Sanand semiconductor jobs growth
... B19: Wholesale potential factor | C19: x | D19: 1 | E19: 1 | F19: 1.2 | G19: 1.3 | H19: =INDEX(D19:G19,Inputs!$D$15) -> 1 | J19: Office pantries (GIFT), industrial canteens (Sanand)
B20: Property tax & society charges (own) | C20: ₹/sqft/yr | D20: 35 | E20: 40 | F20: 30 | G20: 15 | H20: =INDEX(D20:G20,Inputs!$D$15) -> 35
B21: Property appreciation (own) | C21: % p.a. | D21: 0.05 | E21: 0.06 | F21: 0.07 | G21: 0.06 | H21: =INDEX(D21:G21,Inputs!$D$15) -> 0.05
B23: Derived indicators (Base footfall, Specialty mix, rented)
B24: Rent per seat per month | C24: ₹ | D24: =D6*D8/D7 -> 2875 | E24: =E6*E8/E7 -> 4038.4615 | F24: =F6*F8/F7 -> 2750 | G24: =G6*G8/G7 -> 1250 | H24: =H6*H8/H7 -> 2875
B25: Café revenue at steady state (FY28 prices) | C25: ₹ lakh/yr | D25: =D13*D14*D15/Lakh -> 161.28 | E25: =E13*E14*E15/Lakh -> 220.32 | F25: =F13*F14*F15/Lakh -> 143.55 | G25: =G13*G14*G15/Lakh -> 100.1 | H25: =H13*H14*H15/Lakh -> 161.28
B26: Rent as % of steady-state revenue | C26: % | D26: =D6*D8*12/(D13*D14*D15) -> 0.085565476 | E26: =E6*E8*12/(E13*E14*E15) -> 0.11437908 | F26: =F6*F8*12/(F13*F14*F15) -> 0.082758621 | G26: =G6*G8*12/(G13*G14*G15) -> 0.05994006 | H26: =H6*H8*12/(H13*H14*H15) -> 0.085565476
B27: Interiors cost | C27: ₹ lakh | D27: =D6*D11/Lakh -> 26 | E27: =E6*E11/Lakh -> 36 | F27: =F6*F11/Lakh -> 23.4 | G27: =G6*G11/Lakh -> 20 | H27: =H6*H11/Lakh -> 26
B28: Purchase cost of the unit (own case) | C28: ₹ lakh | D28: =D6*D12/Lakh -> 175 | E28: =E6*E12/Lakh -> 288 | F28: =F6*F12/Lakh -> 126 | G28: =G6*G12/Lakh -> 65 | H28: =H6*H12/Lakh -> 175
B29: Gross rental yield on purchase price | C29: % | D29: =D8*12/D12 -> 0.078857143 | E29: =E8*12/E12 -> 0.0875 | F29: =F8*12/F12 -> 0.094285714 | G29: =G8*12/G12 -> 0.092307692 | H29: =H8*12/H12 -> 0.078857143
B31: Site profiles
B32: Prahladnagar | C32: Corporate Road / 100 ft road office & upscale-residential belt. Dense chain competition (Starbucks, Third Wave, Slay, The Dark Roast).
B33: Sindhu Bhavan Road | C33: Ahmedabad's premier F&B high street (Bodakdev). Highest footfall and spend, evening/weekend peaks, highest rents.
B34: GIFT City | C34: India's IFSC: captive, fast-growing white-collar workforce (>12k, target 1 lakh jobs by 2030), few quality cafés, weekday demand.
B35: Sanand | C35: Industrial boom town: Micron ATMP (opened Feb 2026), Tata EV plants; ~50k semicon jobs planned in Gujarat. Cheap space, low ATV, first-mover play.

Sheet Sourcing
B1: Coffee sourcing & roasting economics
B2: Green prices in ₹/kg (Oct 2026). Mix shares must add to 100%. Column J = active mix.
B3: ="Model running: "&Inputs!$D$23 -> Model running: Prahladnagar | Rent | Toll roasting | Specialty mix | Base case
B5: Roasting & packing parameters
B6: Roast loss (moisture & chaff) | C6: % | D6: 0.16 | F6: 1 kg green -> 0.84 kg roasted
B7: Toll-roasting fee | C7: ₹/kg roasted | D7: 180 | F7: Contract roaster roasts your green
B8: Inbound freight, green or roasted | C8: ₹/kg | D8: 25 | F8: Chikmagalur/Coorg to Ahmedabad
B9: In-house roasting variable cost (LPG, power, bags) | C9: ₹/kg roasted | D9: 35 | F9: Roaster labour & AMC are in fixed costs
B10: Café bulk packing | C10: ₹/kg | D10: 10
B11: Retail bag, valve & label | C11: ₹/kg | D11: 48 | F11: ₹12 per 250 g bag
B12: Wholesale packing | C12: ₹/kg | D12: 45
B14: Green coffee type | C14: Units | D14: Green ₹/kg | E14: Roasted, bought ₹/kg | F14: Value | G14: Specialty | H14: Premium | I14: Custom | J14: =INDEX(F14:I14,Inputs!$D$18) -> Specialty
B15: Commodity arabica (Plantation A) | C15: share | D15: 600 | E15: 1050 | F15: 0.5 | G15: 0 | H15: 0 | I15: 0 | J15: =INDEX(F15:I15,Inputs!$D$18) -> 0
B16: Commodity robusta | C16: share | D16: 440 | E16: 900 | F16: 0.5 | G16: 0 | H16: 0 | I16: 0 | J16: =INDEX(F16:I16,Inputs!$D$18) -> 0
B17: Fine robusta (washed) | C17: share | D17: 520 | E17: 1150 | F17: 0 | G17: 0.2 | H17: 0.1 | I17: 0.15 | J17: =INDEX(F17:I17,Inputs!$D$18) -> 0.2
B18: Estate specialty arabica (83-85) | C18: share | D18: 950 | E18: 1700 | F18: 0 | G18: 0.75 | H18: 0.5 | I18: 0.7 | J18: =INDEX(F18:I18,Inputs!$D$18) -> 0.75
B19: Micro-lot (86+) | C19: share | D19: 2200 | E19: 3200 | F19: 0 | G19: 0.05 | H19: 0.4 | I19: 0.15 | J19: =INDEX(F19:I19,Inputs!$D$18) -> 0.05
B20: Share total (must be 100%) | C20: % | F20: =SUM(F15:F19) -> 1 | G20: =SUM(G15:G19) -> 1 | H20: =SUM(H15:H19) -> 1 | I20: =SUM(I15:I19) -> 1 | J20: =INDEX(F20:I20,Inputs!$D$18) -> 1
B21: Blended green price | C21: ₹/kg | F21: =SUMPRODUCT($D$15:$D$19,F15:F19) -> 520 | G21: =SUMPRODUCT($D$15:$D$19,G15:G19) -> 926.5 | H21: =SUMPRODUCT($D$15:$D$19,H15:H19) -> 1407 | I21: =SUMPRODUCT($D$15:$D$19,I15:I19) -> 1073 | J21: =INDEX(F21:I21,Inputs!$D$18) -> 926.5
B22: Blended roasted price if bought | C22: ₹/kg | F22: =SUMPRODUCT($E$15:$E$19,F15:F19) -> 975 | G22: =SUMPRODUCT($E$15:$E$19,G15:G19) -> 1665 | H22: =SUMPRODUCT($E$15:$E$19,H15:H19) -> 2245 | I22: =SUMPRODUCT($E$15:$E$19,I15:I19) -> 1842.5 | J22: =INDEX(F22:I22,Inputs!$D$18) -> 1665
B23: Green coffee in 1 kg roasted | C23: ₹/kg roasted | F23: =F21/(1-$D$6) -> 619.04762 | G23: =G21/(1-$D$6) -> 1102.9762 | H23: =H21/(1-$D$6) -> 1675 | I23: =I21/(1-$D$6) -> 1277.381 | J23: =INDEX(F23:I23,Inputs!$D$18) -> 1102.9762
B25: Cost per kg of roasted coffee, by route (FY28, before green-price index)
B26: Roaster's margin & conversion (buy roasted) | C26: ₹/kg | F26: =F22-F23 -> 355.95238 | G26: =G22-G23 -> 562.02381 | H26: =H22-H23 -> 570 | I26: =I22-I23 -> 565.11905 | J26: =INDEX(F26:I26,Inputs!$D$18) -> 562.02381
B27: Toll fee + freight (toll roasting) | C27: ₹/kg | F27: =$D$7+$D$8 -> 205 | G27: =$D$7+$D$8 -> 205 | H27: =$D$7+$D$8 -> 205 | I27: =$D$7+$D$8 -> 205 | J27: =INDEX(F27:I27,Inputs!$D$18) -> 205
B28: Variable roasting cost + freight (in-house) | C28: ₹/kg | F28: =$D$9+$D$8 -> 60 | G28: =$D$9+$D$8 -> 60 | H28: =$D$9+$D$8 -> 60 | I28: =$D$9+$D$8 -> 60 | J28: =INDEX(F28:I28,Inputs!$D$18) -> 60
B29: Total: Buy roasted | C29: ₹/kg | F29: =F23+F26 -> 975 | G29: =G23+G26 -> 1665 | H29: =H23+H26 -> 2245 | I29: =I23+I26 -> 1842.5 | J29: =INDEX(F29:I29,Inputs!$D$18) -> 1665
B30: Total: Toll roasting | C30: ₹/kg | F30: =F23+F27 -> 824.04762 | G30: =G23+G27 -> 1307.9762 | H30: =H23+H27 -> 1880 | I30: =I23+I27 -> 1482.381 | J30: =INDEX(F30:I30,Inputs!$D$18) -> 1307.9762
B31: Total: In-house roastery (variable only) | C31: ₹/kg | F31: =F23+F28 -> 679.04762 | G31: =G23+G28 -> 1162.9762 | H31: =H23+H28 -> 1735 | I31: =I23+I28 -> 1337.381 | J31: =INDEX(F31:I31,Inputs!$D$18) -> 1162.9762
B32: Coffee cost per 18 g double shot, toll route | C32: ₹ | F32: =F30*18/1000 -> 14.832857 | G32: =G30*18/1000 -> 23.543571 | H32: =H30*18/1000 -> 33.84 | I32: =I30*18/1000 -> 26.682857 | J32: =INDEX(F32:I32,Inputs!$D$18) -> 23.543571
B34: Demand & price effects of the bean mix
B35: Average-bill premium vs Specialty | C35: % | F35: -0.1 | G35: 0 | H35: 0.05 | I35: 0.02 | J35: =INDEX(F35:I35,Inputs!$D$18) -> 0 | L35: Menu pricing the bean quality supports
B36: Footfall effect vs Specialty | C36: % | F36: 0.05 | G36: 0 | H36: -0.05 | I36: 0 | J36: =INDEX(F36:I36,Inputs!$D$18) -> 0 | L36: Value draws a broader crowd; Premium narrows it
B37: Retail bean price (own label) | C37: ₹/kg | F37: 1600 | G37: 2400 | H37: 3600 | I37: 2800 | J37: =INDEX(F37:I37,Inputs!$D$18) -> 2400 | L37: ₹400 / ₹600 / ₹900 / ₹700 per 250 g bag
B38: Wholesale roasted-bean price (FY28) | C38: ₹/kg | F38: 900 | G38: 1450 | H38: 2300 | I38: 1700 | J38: =INDEX(F38:I38,Inputs!$D$18) -> 1450 | L38: To offices, cafés & hotels (in-house roastery only)
B40: Roasting routes (drop-down list)
B41: Route options | F41: Buy roasted | G41: Toll roasting | H41: In-house roastery
B43: Active coffee cost (feeds the Model)
B44: Green coffee per kg roasted, active mix | C44: ₹/kg | J44: =$J$23 -> 1102.9762
B45: Conversion cost per kg, active route | C45: ₹/kg | J45: =CHOOSE(Inputs!$D$17,$J$26,$J$27,$J$28) -> 205
B46: Roasted coffee cost per kg (FY28 basis) | C46: ₹/kg | J46: =$J$44+$J$45 -> 1307.9762
...

Sheet Capex
B1: Capex, property & funding
B2: Unit costs in ₹ (ex-GST, Oct 2026). Amounts in ₹ lakh include the scenario capex-overrun and any Scenarios-sheet capex multiplier.
B3: ="Model running: "&Inputs!$D$23 -> Model running: Prahladnagar | Rent | Toll roasting | Specialty mix | Base case
B5: Equipment & fit-out
B6: Item | C6: Basis | D6: Unit cost ₹ | E6: Quantity | F6: Asset class | G6: ₹ lakh | I6: Notes
B7: Interiors, civil, MEP & design | C7: per sqft (site) | D7: =Locations!$H$11 -> 2600 | E7: =Locations!$H$6 -> 1000 | F7: Interiors | G7: =D7*E7*(1+Inputs!$D$56)*Scenarios!$D$40/Lakh -> 27.3 | I7: Site-specific rate from Locations
B8: HVAC (ductable / split ACs) | C8: per sqft | D8: 450 | E8: =Locations!$H$6 -> 1000 | F8: Equipment | G8: =D8*E8*(1+Inputs!$D$56)*Scenarios!$D$40/Lakh -> 4.725
B9: Electrical upgrade, UPS & DG share | C9: lump sum | D9: 250000 | E9: =1 -> 1 | F9: Equipment | G9: =D9*E9*(1+Inputs!$D$56)*Scenarios!$D$40/Lakh -> 2.625
B10: Espresso machine, 2-group multi-boiler | C10: lump sum | D10: 800000 | E10: =1 -> 1 | F10: Equipment | G10: =D10*E10*(1+Inputs!$D$56)*Scenarios!$D$40/Lakh -> 8.4 | I10: La Marzocco Linea PB 2GR ₹11.26 lakh + GST; Brewlyn 2GR ₹6.30 lakh
B11: Grinders: 2 on-demand espresso + 1 filter | C11: lump sum | D11: 420000 | E11: =1 -> 1 | F11: Equipment | G11: =D11*E11*(1+Inputs!$D$56)*Scenarios!$D$40/Lakh -> 4.41
B12: Brew bar, cold-brew kit & water boiler | C12: lump sum | D12: 150000 | E12: =1 -> 1 | F12: Equipment | G12: =D12*E12*(1+Inputs!$D$56)*Scenarios!$D$40/Lakh -> 1.575
B13: Kitchen equipment & refrigeration | C13: lump sum | D13: 550000 | E13: =1 -> 1 | F13: Equipment | G13: =D13*E13*(1+Inputs!$D$56)*Scenarios!$D$40/Lakh -> 5.775
B14: Water treatment (RO + softener + remineralisation) | C14: lump sum | D14: 100000 | E14: =1 -> 1 | F14: Equipment | G14: =D14*E14*(1+Inputs!$D$56)*Scenarios!$D$40/Lakh -> 1.05
B15: Furniture & seating | C15: per seat | D15: 12000 | E15: =Locations!$H$7 -> 40 | F15: Furniture | G15: =D15*E15*(1+Inputs!$D$56)*Scenarios!$D$40/Lakh -> 5.04
B16: Crockery, glassware & smallwares | C16: lump sum | D16: 150000 | E16: =1 -> 1 | F16: Furniture | G16: =D16*E16*(1+Inputs!$D$56)*Scenarios!$D$40/Lakh -> 1.575
B17: Signage & branding | C17: lump sum | D17: 200000 | E17: =1 -> 1 | F17: Furniture | G17: =D17*E17*(1+Inputs!$D$56)*Scenarios!$D$40/Lakh -> 2.1
B18: POS, CCTV, audio & Wi-Fi | C18: lump sum | D18: 180000 | E18: =1 -> 1 | F18: IT | G18: =D18*E18*(1+Inputs!$D$56)*Scenarios!$D$40/Lakh -> 1.89
B19: 3 kg drum roaster (Indian-made) incl. install | C19: in-house only | D19: 900000 | E19: =Inputs!$D$21 -> 0 | F19: Roastery | G19: =D19*E19*(1+Inputs!$D$56)*Scenarios!$D$40/Lakh -> 0 | I19: Aaroasta (Rajkot) ARST-3, LPG, 6-9 kg/hour
B20: Afterburner, chimney & ducting | C20: in-house only | D20: 250000 | E20: =Inputs!$D$21 -> 0 | F20: Roastery | G20: =D20*E20*(1+Inputs!$D$56)*Scenarios!$D$40/Lakh -> 0
B21: QC & packing kit (moisture meter, sealer, sample roaster) | C21: in-house only | D21: 150000 | E21: =Inputs!$D$21 -> 0 | F21: Roastery | G21: =D21*E21*(1+Inputs!$D$56)*Scenarios!$D$40/Lakh -> 0
B22: Roastery area fit-out (150 sqft) | C22: roastery sqft | D22: =Locations!$H$11 -> 2600 | E22: =Inputs!$D$21*Inputs!$D$113 -> 0 | F22: Interiors | G22: =D22*E22*(1+Inputs!$D$56)*Scenarios!$D$40/Lakh -> 0
B23: Café & roastery capex | G23: =SUM(G7:G22) -> 66.465
B25: Premises (own case)
B26: Area occupied (café + roastery if in-house) | C26: sqft | G26: =Locations!$H$6+Inputs!$D$21*Inputs!$D$113 -> 1000
B27: Purchase price, active location | C27: ₹/sqft | G27: =Locations!$H$12 -> 17500
B28: Purchase price | C28: ₹ lakh | G28: =Inputs!$D$20*$G$26*$G$27/Lakh -> 0
B29: Stamp duty & registration | C29: ₹ lakh | G29: =$G$28*Inputs!$D$127 -> 0
B30: Legal & brokerage | C30: ₹ lakh | G30: =$G$28*Inputs!$D$128 -> 0
B31: Total property cost | C31: ₹ lakh | G31: =$G$28+$G$29+$G$30 -> 0
B32: of which land (not depreciated) | C32: ₹ lakh | G32: =$G$31*Inputs!$D$129 -> 0
B33: of which building | C33: ₹ lakh | G33: =$G$31-$G$32 -> 0
B35: Initial capex by asset class
B36: Asset class | D36: ₹ lakh | E36: Book life | F36: Tax WDV rate
B37: Interiors | D37: =SUMIF($F$7:$F$22,"Interiors",$G$7:$G$22) -> 27.3 | E37: 9 | F37: 0.1
B38: Equipment | D38: =SUMIF($F$7:$F$22,"Equipment",$G$7:$G$22) -> 28.56 | E38: 8 | F38: 0.15
B39: Furniture | D39: =SUMIF($F$7:$F$22,"Furniture",$G$7:$G$22) -> 8.715 | E39: 8 | F39: 0.1
B40: IT | D40: =SUMIF($F$7:$F$22,"IT",$G$7:$G$22) -> 1.89 | E40: 4 | F40: 0.4
B41: Roastery | D41: =SUMIF($F$7:$F$22,"Roastery",$G$7:$G$22) -> 0 | E41: 10 | F41: 0.15
B42: Building | D42: =$G$33 -> 0 | E42: 60 | F42: 0.1
B43: Land | D43: =$G$32 -> 0 | E43: 0 | F43: 0
...

Sheet Model
B1: Model: three statements & schedules
B2: ₹ lakh unless stated. Statements contain links only; all workings are in the schedules below.
B3: ="Model running: "&Inputs!$D$23 -> Model running: Prahladnagar | Rent | Toll roasting | Specialty mix | Base case
B5: ₹ lakh unless stated | C5: Units | D5: Value | F5: =Inputs!F5 -> 2027 | G5: =Inputs!G5 -> 2028 | H5: =Inputs!H5 -> 2029 | I5: =Inputs!I5 -> 2030 | J5: =Inputs!J5 -> 2031 | K5: =Inputs!K5 -> 2032 | L5: =Inputs!L5 -> 2033 | M5: =Inputs!M5 -> 2034 | ... P5: =Inputs!P5 -> 2037
B6: Period (Y0 = pre-opening fit-out year) | F6: =F5-Inputs!$D$26 -> 0 | G6: =G5-Inputs!$D$26 -> 1 | H6: =H5-Inputs!$D$26 -> 2 | I6: =I5-Inputs!$D$26 -> 3 | J6: =J5-Inputs!$D$26 -> 4 | K6: =K5-Inputs!$D$26 -> 5 | L6: =L5-Inputs!$D$26 -> 6 | M6: =M5-Inputs!$D$26 -> 7 | ... P6: =P5-Inputs!$D$26 -> 10
B7: Operating flag | C7: 1/0 | F7: =IF(F6>=1,1,0) -> 0 | G7: =IF(G6>=1,1,0) -> 1 | H7: =IF(H6>=1,1,0) -> 1 | I7: =IF(I6>=1,1,0) -> 1 | J7: =IF(J6>=1,1,0) -> 1 | K7: =IF(K6>=1,1,0) -> 1 | L7: =IF(L6>=1,1,0) -> 1 | M7: =IF(M6>=1,1,0) -> 1 | ... P7: =IF(P6>=1,1,0) -> 1
B8: Food & supplies price index | C8: x | F8: =(1+Inputs!$D$73)^MAX(0,F6-1) -> 1 | G8: =(1+Inputs!$D$73)^MAX(0,G6-1) -> 1 | H8: =(1+Inputs!$D$73)^MAX(0,H6-1) -> 1.05 | I8: =(1+Inputs!$D$73)^MAX(0,I6-1) -> 1.1025 | J8: =(1+Inputs!$D$73)^MAX(0,J6-1) -> 1.157625 | K8: =(1+Inputs!$D$73)^MAX(0,K6-1) -> 1.2155063 | L8: =(1+Inputs!$D$73)^MAX(0,L6-1) -> 1.2762816 | M8: =(1+Inputs!$D$73)^MAX(0,M6-1) -> 1.3400956 | ... P8: =(1+Inputs!$D$73)^MAX(0,P6-1) -> 1.5513282
B9: General cost index | C9: x | F9: =(1+Inputs!$D$111)^MAX(0,F6-1) -> 1 | G9: =(1+Inputs!$D$111)^MAX(0,G6-1) -> 1 | H9: =(1+Inputs!$D$111)^MAX(0,H6-1) -> 1.05 | I9: =(1+Inputs!$D$111)^MAX(0,I6-1) -> 1.1025 | J9: =(1+Inputs!$D$111)^MAX(0,J6-1) -> 1.157625 | K9: =(1+Inputs!$D$111)^MAX(0,K6-1) -> 1.2155063 | L9: =(1+Inputs!$D$111)^MAX(0,L6-1) -> 1.2762816 | M9: =(1+Inputs!$D$111)^MAX(0,M6-1) -> 1.3400956 | ... P9: =(1+Inputs!$D$111)^MAX(0,P6-1) -> 1.5513282
B11: Income statement
B12: Beverages | C12: ₹ lakh | F12: =F92 -> 0 | G12: =G92 -> 64.99584 | H12: =H92 -> 89.244288 | I12: =I92 -> 110.24294 | J12: =J92 -> 118.64897 | K12: =K92 -> 127.69595 | L12: =L92 -> 137.43277 | M12: =M92 -> 147.91202 | ... P12: =P92 -> 184.39237
B13: Food | C13: ₹ lakh | F13: =F93 -> 0 | G13: =G93 -> 31.4496 | H13: =H93 -> 43.18272 | I13: =I93 -> 53.34336 | J13: =J93 -> 57.410791 | K13: =K93 -> 61.788364 | L13: =L93 -> 66.499727 | M13: =M93 -> 71.570331 | ... P13: =P93 -> 89.222116
B14: Retail beans & merchandise | C14: ₹ lakh | F14: =F94 -> 0 | G14: =G94 -> 8.38656 | H14: =H94 -> 11.515392 | I14: =I94 -> 14.224896 | J14: =J94 -> 15.309544 | K14: =K94 -> 16.476897 | L14: =L94 -> 17.73326 | M14: =M94 -> 19.085422 | ... P14: =P94 -> 23.792564
B15: Wholesale roasted beans | C15: ₹ lakh | F15: =F97 -> 0 | G15: =G97 -> 0 | H15: =H97 -> 0 | I15: =I97 -> 0 | J15: =J97 -> 0 | K15: =K97 -> 0 | L15: =L97 -> 0 | M15: =M97 -> 0 | ... P15: =P97 -> 0
B16: Revenue | C16: ₹ lakh | F16: =SUM(F12:F15) -> 0 | G16: =SUM(G12:G15) -> 104.832 | H16: =SUM(H12:H15) -> 143.9424 | I16: =SUM(I12:I15) -> 177.8112 | J16: =SUM(J12:J15) -> 191.3693 | K16: =SUM(K12:K15) -> 205.96121 | L16: =SUM(L12:L15) -> 221.66576 | M16: =SUM(M12:M15) -> 238.56777 | ... P16: =SUM(P12:P15) -> 297.40705
B17: growth | C17: % | H17: =IF(G16>0,H16/G16-1,0) -> 0.37307692 | I17: =IF(H16>0,I16/H16-1,0) -> 0.23529412 | J17: =IF(I16>0,J16/I16-1,0) -> 0.07625 | K17: =IF(J16>0,K16/J16-1,0) -> 0.07625 | L17: =IF(K16>0,L16/K16-1,0) -> 0.07625 | M17: =IF(L16>0,M16/L16-1,0) -> 0.07625 | N17: =IF(M16>0,N16/M16-1,0) -> 0.07625 | O17: =IF(N16>0,O16/N16-1,0) -> 0.07625 | P17: =IF(O16>0,P16/O16-1,0) -> 0.07625
B18: Cost of goods sold | C18: ₹ lakh | F18: =-F114 -> 0 | G18: =-G114 -> -31.702697 | H18: =-H114 -> -43.299044 | I18: =-I114 -> -53.206899 | J18: =-J114 -> -56.967774 | K18: =-K114 -> -60.999582 | L18: =-L114 -> -65.321642 | M18: =-M114 -> -69.954672 | ... P18: =-P114 -> -85.954798
B19: Gross profit | C19: ₹ lakh | F19: =F16+F18 -> 0 | G19: =G16+G18 -> 73.129303 | H19: =H16+H18 -> 100.64336 | I19: =I16+I18 -> 124.6043 | J19: =J16+J18 -> 134.40153 | K19: =K16+K18 -> 144.96163 | L19: =L16+L18 -> 156.34411 | M19: =M16+M18 -> 168.6131 | ... P19: =P16+P18 -> 211.45226
B20: gross margin | C20: % | F20: =IF(F16>0,F19/F16,0) -> 0 | G20: =IF(G16>0,G19/G16,0) -> 0.69758569 | H20: =IF(H16>0,H19/H16,0) -> 0.69919187 | I20: =IF(I16>0,I19/I16,0) -> 0.70076745 | J20: =IF(J16>0,J19/J16,0) -> 0.70231499 | K20: =IF(K16>0,K19/K16,0) -> 0.70382976 | L20: =IF(L16>0,L19/L16,0) -> 0.70531469 | M20: =IF(M16>0,M19/M16,0) -> 0.70677233 | ... P20: =IF(P16>0,P19/P16,0) -> 0.71098601
B21: Staff costs | C21: ₹ lakh | F21: =-F121 -> 0 | G21: =-G121 -> -39.054 | H21: =-H121 -> -42.17832 | I21: =-I121 -> -45.552586 | J21: =-J121 -> -49.811752 | K21: =-K121 -> -54.477453 | L21: =-L121 -> -59.589251 | M21: =-M121 -> -65.190629 | ... P21: =-P121 -> -85.434393
B22: Rent, CAM & property tax | C22: ₹ lakh | F22: =-(F122+F123+F124) -> 0 | G22: =-(G122+G123+G124) -> -14.28 | H22: =-(H122+H123+H124) -> -14.994 | I22: =-(I122+I123+I124) -> -15.7437 | J22: =-(J122+J123+J124) -> -16.530885 | K22: =-(K122+K123+K124) -> -17.357429 | L22: =-(L122+L123+L124) -> -18.225301 | M22: =-(M122+M123+M124) -> -19.136566 | ... P22: =-(P122+P123+P124) -> -22.152967
B23: Electricity, gas & water | C23: ₹ lakh | F23: =-(F125+F126) -> 0 | G23: =-(G125+G126) -> -7.5 | H23: =-(H125+H126) -> -7.818 | I23: =-(I125+I126) -> -8.14962 | J23: =-(J125+J126) -> -8.4954498 | K23: =-(K125+K126) -> -8.856105 | L23: =-(L125+L126) -> -9.2322284 | M23: =-(M125+M126) -> -9.6244906 | ... P23: =-(P125+P126) -> -10.905268
B24: Marketing | C24: ₹ lakh | F24: =-F127 -> 0 | G24: =-G127 -> -5.2416 | H24: =-H127 -> -4.318272 | I24: =-I127 -> -5.334336 | J24: =-J127 -> -5.7410791 | K24: =-K127 -> -6.1788364 | L24: =-L127 -> -6.6499727 | M24: =-M127 -> -7.1570331 | ... P24: =-P127 -> -8.9222116
B25: Aggregator & payment fees | C25: ₹ lakh | F25: =-(F130+F131) -> 0 | G25: =-(G130+G131) -> -4.5549504 | H25: =-(H130+H131) -> -6.2542973 | I25: =-(I130+I131) -> -7.7258966 | J25: =-(J130+J131) -> -8.3149963 | K25: =-(K130+K131) -> -8.9490147 | L25: =-(L130+L131) -> -9.6313771 | M25: =-(M130+M131) -> -10.36577 | ... P25: =-(P130+P131) -> -12.922336
B26: Repairs, maintenance & AMC | C26: ₹ lakh | F26: =-(F128+F129) -> 0 | G26: =-(G128+G129) -> -2.17248 | H26: =-(H128+H129) -> -2.789136 | I26: =-(I128+I129) -> -3.328668 | J26: =-(J128+J129) -> -3.5651146 | K26: =-(K128+K129) -> -3.818722 | L26: =-(L128+L129) -> -4.0907553 | M26: =-(M128+M129) -> -4.3825739 | ... P26: =-(P128+P129) -> -5.3919027
B27: Admin, wholesale selling & other | C27: ₹ lakh | F27: =-(F132+F133+F134) -> 0 | G27: =-(G132+G133+G134) -> -4.04832 | H27: =-(H132+H133+H134) -> -4.589424 | I27: =-(I132+I133+I134) -> -5.085612 | J27: =-(J132+J133+J134) -> -5.386568 | K27: =-(K132+K133+K134) -> -5.7061309 | L27: =-(L132+L133+L134) -> -6.0455022 | M27: =-(M132+M133+M134) -> -6.4059646 | ... P27: =-(P132+P133+P134) -> -7.6280552
B28: Pre-opening expenses | C28: ₹ lakh | F28: =-F135 -> -11.0545 | G28: =-G135 -> 0 | H28: =-H135 -> 0 | I28: =-I135 -> 0 | J28: =-J135 -> 0 | K28: =-K135 -> 0 | L28: =-L135 -> 0 | M28: =-M135 -> 0 | ... P28: =-P135 -> 0
B29: EBITDA | C29: ₹ lakh | F29: =SUM(F19,F21:F28) -> -11.0545 | G29: =SUM(G19,G21:G28) -> -3.722047 | H29: =SUM(H19,H21:H28) -> 17.701906 | I29: =SUM(I19,I21:I28) -> 33.683883 | J29: =SUM(J19,J21:J28) -> 36.555685 | K29: =SUM(K19,K21:K28) -> 39.61794 | L29: =SUM(L19,L21:L28) -> 42.879726 | M29: =SUM(M19,M21:M28) -> 46.350071 | ... P29: =SUM(P19,P21:P28) -> 58.095121
B30: EBITDA margin | C30: % | F30: =IF(F16>0,F29/F16,0) -> 0 | G30: =IF(G16>0,G29/G16,0) -> -0.035504875 | H30: =IF(H16>0,H29/H16,0) -> 0.1229791 | I30: =IF(I16>0,I29/I16,0) -> 0.18943623 | J30: =IF(J16>0,J29/J16,0) -> 0.19102168 | K30: =IF(K16>0,K29/K16,0) -> 0.19235632 | L30: =IF(L16>0,L29/L16,0) -> 0.19344317 | M30: =IF(M16>0,M29/M16,0) -> 0.19428471 | ... P30: =IF(P16>0,P29/P16,0) -> 0.19533875
B31: Depreciation | C31: ₹ lakh | F31: =-F157 -> 0 | G31: =-G157 -> -8.1652083 | H31: =-H157 -> -8.4797043 | I31: =-I157 -> -8.9115315 | J31: =-J157 -> -9.4449651 | K31: =-K157 -> -9.546573 | L31: =-L157 -> -10.164457 | M31: =-M157 -> -12.813222 | ... P31: =-P157 -> -5.8961331
B32: EBIT | C32: ₹ lakh | F32: =F29+F31 -> -11.0545 | G32: =G29+G31 -> -11.887255 | H32: =H29+H31 -> 9.222202 | I32: =I29+I31 -> 24.772351 | J32: =J29+J31 -> 27.11072 | K32: =K29+K31 -> 30.071367 | L32: =L29+L31 -> 32.71527 | M32: =M29+M31 -> 33.536849 | ... P32: =P29+P31 -> 52.198988
B33: Interest expense | C33: ₹ lakh | F33: =-(F204+F210) -> 0 | G33: =-(G204+G210) -> -3.652 | H33: =-(H204+H210) -> -2.9216 | I33: =-(I204+I210) -> -2.1912 | J33: =-(J204+J210) -> -1.4608 | K33: =-(K204+K210) -> -0.7304 | L33: =-(L204+L210) -> 0 | M33: =-(M204+M210) -> 0 | ... P33: =-(P204+P210) -> 0
B34: Interest income | C34: ₹ lakh | F34: =F211 -> 0 | G34: =G211 -> 0.76434 | H34: =H211 -> 0.12317974 | I34: =I211 -> 0.34997769 | J34: =J211 -> 1.1799754 | K34: =K211 -> 1.944653 | L34: =L211 -> 2.8323472 | M34: =M211 -> 3.6676624 | ... P34: =P211 -> 8.345452
B35: Profit before tax | C35: ₹ lakh | F35: =F32+F33+F34 -> -11.0545 | G35: =G32+G33+G34 -> -14.774915 | H35: =H32+H33+H34 -> 6.4237817 | I35: =I32+I33+I34 -> 22.931129 | J35: =J32+J33+J34 -> 26.829895 | K35: =K32+K33+K34 -> 31.28562 | L35: =L32+L33+L34 -> 35.547617 | M35: =M32+M33+M34 -> 37.204511 | ... P35: =P32+P33+P34 -> 60.54444
B36: Current tax | C36: ₹ lakh | F36: =-F186 -> 0 | G36: =-G186 -> 0 | H36: =-H186 -> 0 | I36: =-I186 -> -1.4185691 | J36: =-J186 -> -7.5145407 | K36: =-K186 -> -8.7685329 | L36: =-L186 -> -9.8613591 | M36: =-M186 -> -10.821242 | ... P36: =-P186 -> -15.192589
B37: Deferred tax | C37: ₹ lakh | F37: =-F174 -> 0 | G37: =-G174 -> -0.14955522 | H37: =-H174 -> 0.19209162 | I37: =-I174 -> 0.488736 | J37: =-J174 -> 0.76199261 | K37: =-K174 -> 0.89456793 | L37: =-L174 -> 0.91473493 | M37: =-M174 -> 1.4576109 | ... P37: =-P174 -> -0.045235453
B38: Profit after tax | C38: ₹ lakh | F38: =F35+F36+F37 -> -11.0545 | G38: =G35+G36+G37 -> -14.924471 | H38: =H35+H36+H37 -> 6.6158733 | I38: =I35+I36+I37 -> 22.001296 | J38: =J35+J36+J37 -> 20.077347 | K38: =K35+K36+K37 -> 23.411655 | L38: =L35+L36+L37 -> 26.600993 | M38: =M35+M36+M37 -> 27.84088 | ... P38: =P35+P36+P37 -> 45.306616
B39: net margin | C39: % | F39: =IF(F16>0,F38/F16,0) -> 0 | G39: =IF(G16>0,G38/G16,0) -> -0.1423656 | H39: =IF(H16>0,H38/H16,0) -> 0.04596195 | I39: =IF(I16>0,I38/I16,0) -> 0.12373403 | J39: =IF(J16>0,J38/J16,0) -> 0.10491415 | K39: =IF(K16>0,K38/K16,0) -> 0.11367022 | L39: =IF(L16>0,L38/L16,0) -> 0.12000497 | M39: =IF(M16>0,M38/M16,0) -> 0.11670009 | ... P39: =IF(P16>0,P38/P16,0) -> 0.15233874
B41: Cash flow statement
B42: Profit after tax | C42: ₹ lakh | F42: =F38 -> -11.0545 | G42: =G38 -> -14.924471 | H42: =H38 -> 6.6158733 | I42: =I38 -> 22.001296 | J42: =J38 -> 20.077347 | K42: =K38 -> 23.411655 | L42: =L38 -> 26.600993 | M42: =M38 -> 27.84088 | ... P42: =P38 -> 45.306616
B43: Add: depreciation | C43: ₹ lakh | F43: =F157 -> 0 | G43: =G157 -> 8.1652083 | H43: =H157 -> 8.4797043 | I43: =I157 -> 8.9115315 | J43: =J157 -> 9.4449651 | K43: =K157 -> 9.546573 | L43: =L157 -> 10.164457 | M43: =M157 -> 12.813222 | ... P43: =P157 -> 5.8961331
...

Sheet DCF
B1: DCF valuation (FCFF)
B2: Valuation date 31 March 2027 (end of Y0). Y0 investment is undiscounted; Y1-Y10 discounted at WACC; Gordon-growth terminal value at Y10.
B3: ="Model running: "&Inputs!$D$23 -> Model running: Prahladnagar | Rent | Toll roasting | Specialty mix | Base case
B5: ₹ lakh unless stated | C5: Units | D5: Value | F5: =Model!F5 -> 2027 | G5: =Model!G5 -> 2028 | H5: =Model!H5 -> 2029 | I5: =Model!I5 -> 2030 | J5: =Model!J5 -> 2031 | K5: =Model!K5 -> 2032 | L5: =Model!L5 -> 2033 | M5: =Model!M5 -> 2034 | ... P5: =Model!P5 -> 2037
B6: Period (Y0 = pre-opening fit-out year) | F6: =F5-Inputs!$D$26 -> 0 | G6: =G5-Inputs!$D$26 -> 1 | H6: =H5-Inputs!$D$26 -> 2 | I6: =I5-Inputs!$D$26 -> 3 | J6: =J5-Inputs!$D$26 -> 4 | K6: =K5-Inputs!$D$26 -> 5 | L6: =L5-Inputs!$D$26 -> 6 | M6: =M5-Inputs!$D$26 -> 7 | ... P6: =P5-Inputs!$D$26 -> 10
B7: Free cash flow to the firm
B8: EBITDA | C8: ₹ lakh | F8: =Model!F29 -> -11.0545 | G8: =Model!G29 -> -3.722047 | H8: =Model!H29 -> 17.701906 | I8: =Model!I29 -> 33.683883 | J8: =Model!J29 -> 36.555685 | K8: =Model!K29 -> 39.61794 | L8: =Model!L29 -> 42.879726 | M8: =Model!M29 -> 46.350071 | ... P8: =Model!P29 -> 58.095121
B9: Less: depreciation | C9: ₹ lakh | F9: =-Model!F157 -> 0 | G9: =-Model!G157 -> -8.1652083 | H9: =-Model!H157 -> -8.4797043 | I9: =-Model!I157 -> -8.9115315 | J9: =-Model!J157 -> -9.4449651 | K9: =-Model!K157 -> -9.546573 | L9: =-Model!L157 -> -10.164457 | M9: =-Model!M157 -> -12.813222 | ... P9: =-Model!P157 -> -5.8961331
B10: EBIT | C10: ₹ lakh | F10: =F8+F9 -> -11.0545 | G10: =G8+G9 -> -11.887255 | H10: =H8+H9 -> 9.222202 | I10: =I8+I9 -> 24.772351 | J10: =J8+J9 -> 27.11072 | K10: =K8+K9 -> 30.071367 | L10: =L8+L9 -> 32.71527 | M10: =M8+M9 -> 33.536849 | ... P10: =P8+P9 -> 52.198988
B11: Unlevered tax (as if no debt)
B12: EBIT + book dep - tax dep | C12: ₹ lakh | F12: =F10+Model!F157-Model!F171 -> -11.0545 | G12: =G10+Model!G157-Model!G171 -> -12.481483 | H12: =H10+Model!H157-Model!H171 -> 9.9854395 | I12: =I10+Model!I157-Model!I171 -> 26.714246 | J12: =J10+Model!J157-Model!J171 -> 30.138345 | K12: =K10+Model!K157-Model!K171 -> 33.625754 | L12: =L10+Model!L157-Model!L171 -> 36.349785 | M12: =M10+Model!M157-Model!M171 -> 39.328374 | ... P12: =P10+Model!P157-Model!P171 -> 52.019254
B13: Losses brought forward | C13: ₹ lakh | G13: =F16 -> 11.0545 | H13: =G16 -> 23.535983 | I13: =H16 -> 13.550544 | J13: =I16 -> 0 | K13: =J16 -> 0 | L13: =K16 -> 0 | M13: =L16 -> 0 | N13: =M16 -> 0 | ... P13: =O16 -> 0
B14: Losses added | C14: ₹ lakh | F14: =MAX(0,-F12) -> 11.0545 | G14: =MAX(0,-G12) -> 12.481483 | H14: =MAX(0,-H12) -> 0 | I14: =MAX(0,-I12) -> 0 | J14: =MAX(0,-J12) -> 0 | K14: =MAX(0,-K12) -> 0 | L14: =MAX(0,-L12) -> 0 | M14: =MAX(0,-M12) -> 0 | ... P14: =MAX(0,-P12) -> 0
B15: Losses used | C15: ₹ lakh | F15: =MIN(N(F13),MAX(0,F12)) -> 0 | G15: =MIN(N(G13),MAX(0,G12)) -> 0 | H15: =MIN(N(H13),MAX(0,H12)) -> 9.9854395 | I15: =MIN(N(I13),MAX(0,I12)) -> 13.550544 | J15: =MIN(N(J13),MAX(0,J12)) -> 0 | K15: =MIN(N(K13),MAX(0,K12)) -> 0 | L15: =MIN(N(L13),MAX(0,L12)) -> 0 | M15: =MIN(N(M13),MAX(0,M12)) -> 0 | ... P15: =MIN(N(P13),MAX(0,P12)) -> 0
B16: Losses carried forward | C16: ₹ lakh | F16: =F13+F14-F15 -> 11.0545 | G16: =G13+G14-G15 -> 23.535983 | H16: =H13+H14-H15 -> 13.550544 | I16: =I13+I14-I15 -> 0 | J16: =J13+J14-J15 -> 0 | K16: =K13+K14-K15 -> 0 | L16: =L13+L14-L15 -> 0 | M16: =M13+M14-M15 -> 0 | ... P16: =P13+P14-P15 -> 0
B17: Unlevered tax | C17: ₹ lakh | F17: =(MAX(0,F12)-F15)*TaxRate -> 0 | G17: =(MAX(0,G12)-G15)*TaxRate -> 0 | H17: =(MAX(0,H12)-H15)*TaxRate -> 0 | I17: =(MAX(0,I12)-I15)*TaxRate -> 3.3130406 | J17: =(MAX(0,J12)-J15)*TaxRate -> 7.5852186 | K17: =(MAX(0,K12)-K15)*TaxRate -> 8.4629297 | L17: =(MAX(0,L12)-L15)*TaxRate -> 9.148514 | M17: =(MAX(0,M12)-M15)*TaxRate -> 9.8981651 | ... P17: =(MAX(0,P12)-P15)*TaxRate -> 13.092206
B18: Free cash flow
B19: NOPAT (EBIT - unlevered tax) | C19: ₹ lakh | F19: =F10-F17 -> -11.0545 | G19: =G10-G17 -> -11.887255 | H19: =H10-H17 -> 9.222202 | I19: =I10-I17 -> 21.459311 | J19: =J10-J17 -> 19.525501 | K19: =K10-K17 -> 21.608438 | L19: =L10-L17 -> 23.566756 | M19: =M10-M17 -> 23.638684 | ... P19: =P10-P17 -> 39.106782
B20: Add: depreciation | C20: ₹ lakh | F20: =Model!F157 -> 0 | G20: =Model!G157 -> 8.1652083 | H20: =Model!H157 -> 8.4797043 | I20: =Model!I157 -> 8.9115315 | J20: =Model!J157 -> 9.4449651 | K20: =Model!K157 -> 9.546573 | L20: =Model!L157 -> 10.164457 | M20: =Model!M157 -> 12.813222 | ... P20: =Model!P157 -> 5.8961331
B21: Less: capex incl. property | C21: ₹ lakh | F21: =-Model!F148 -> -66.465 | G21: =-Model!G148 -> -1.57248 | H21: =-Model!H148 -> -2.159136 | I21: =-Model!I148 -> -2.667168 | J21: =-Model!J148 -> -2.8705396 | K21: =-Model!K148 -> -3.0894182 | L21: =-Model!L148 -> -14.816306 | M21: =-Model!M148 -> -3.5785165 | ... P21: =-Model!P148 -> -4.4611058
B22: Less: increase in working capital | C22: ₹ lakh | F22: =-Model!F194 -> 0 | G22: =-Model!G194 -> -1.2068196 | H22: =-Model!H194 -> -0.43440114 | I22: =-Model!I194 -> -0.36698081 | J22: =-Model!J194 -> -0.13284104 | K22: =-Model!K194 -> -0.14188566 | L22: =-Model!L194 -> -0.15152823 | M22: =-Model!M194 -> -0.16180917 | ... P22: =-Model!P194 -> -0.1971548
B23: Less: rent deposit | C23: ₹ lakh | F23: =-Model!F195 -> -4.6 | G23: =-Model!G195 -> 0 | H23: =-Model!H195 -> 0 | I23: =-Model!I195 -> 0 | J23: =-Model!J195 -> 0 | K23: =-Model!K195 -> 0 | L23: =-Model!L195 -> 0 | M23: =-Model!M195 -> 0 | ... P23: =-Model!P195 -> 0
B24: Free cash flow to firm | C24: ₹ lakh | F24: =SUM(F19:F23) -> -82.1195 | G24: =SUM(G19:G23) -> -6.5013466 | H24: =SUM(H19:H23) -> 15.108369 | I24: =SUM(I19:I23) -> 27.336694 | J24: =SUM(J19:J23) -> 25.967086 | K24: =SUM(K19:K23) -> 27.923707 | L24: =SUM(L19:L23) -> 18.763378 | M24: =SUM(M19:M23) -> 32.71158 | ... P24: =SUM(P19:P23) -> 40.344655
B25: Discount period | C25: years | F25: =F6 -> 0 | G25: =G6-0.5*Inputs!$D$163 -> 1 | H25: =H6-0.5*Inputs!$D$163 -> 2 | I25: =I6-0.5*Inputs!$D$163 -> 3 | J25: =J6-0.5*Inputs!$D$163 -> 4 | K25: =K6-0.5*Inputs!$D$163 -> 5 | L25: =L6-0.5*Inputs!$D$163 -> 6 | M25: =M6-0.5*Inputs!$D$163 -> 7 | N25: =N6-0.5*Inputs!$D$163 -> 8 | ... P25: =P6-0.5*Inputs!$D$163 -> 10
B26: Discount factor | C26: x | F26: =1/(1+$D$41)^F25 -> 1 | G26: =1/(1+$D$41)^G25 -> 0.86091563 | H26: =1/(1+$D$41)^H25 -> 0.74117573 | I26: =1/(1+$D$41)^I25 -> 0.63808977 | J26: =1/(1+$D$41)^J25 -> 0.54934146 | K26: =1/(1+$D$41)^K25 -> 0.47293665 | L26: =1/(1+$D$41)^L25 -> 0.40715856 | M26: =1/(1+$D$41)^M25 -> 0.35052917 | ... P26: =1/(1+$D$41)^P25 -> 0.22366908
B27: Present value of FCFF | C27: ₹ lakh | F27: =F24*F26 -> -82.1195 | G27: =G24*G26 -> -5.5971109 | H27: =H24*H26 -> 11.197957 | I27: =I24*I26 -> 17.443264 | J27: =J24*J26 -> 14.264797 | K27: =K24*K26 -> 13.206144 | L27: =L24*L26 -> 7.6396697 | M27: =M24*M26 -> 11.466363 | ... P27: =P24*P26 -> 9.0238517
B29: Cost of capital
B30: Risk-free rate | C30: % | D30: =Inputs!$D$155 -> 0.0729
B31: Equity risk premium | C31: % | D31: =Inputs!$D$156 -> 0.0708
B32: Unlevered beta | C32: x | D32: =Inputs!$D$157 -> 0.8
B33: Debt / (debt + equity), from funding plan | C33: % | D33: =Capex!$G$59 -> 0.3279725
B34: Debt / equity | C34: x | D34: =IF($D$33<1,$D$33/(1-$D$33),0) -> 0.48803434
B35: Relevered beta | C35: x | D35: =$D$32*(1+(1-TaxRate)*$D$34) -> 1.0921647
B36: Size & single-outlet premium | C36: % | D36: =Inputs!$D$158 -> 0.05
B37: Cost of equity | C37: % | D37: =$D$30+$D$35*$D$31+$D$36 -> 0.20022526
B38: Cost of debt, pre-tax | C38: % | D38: =Capex!$G$60 -> 0.11
B39: Cost of debt, after tax | C39: % | D39: =$D$38*(1-TaxRate) -> 0.0823152
B40: WACC, calculated | C40: % | D40: =(1-$D$33)*$D$37+$D$33*$D$39 -> 0.161554
B41: WACC used (incl. any Scenarios-sheet change) | C41: % | D41: =$D$40+Scenarios!$D$43 -> 0.161554
B42: Terminal growth used | C42: % | D42: =Scenarios!$D$44 -> 0.04
...

Sheet Scenarios
B1: Scenarios & sensitivities
B2: Live Excel data tables: each cell re-runs the full model. Keep the blue override cells at their default (0 or 1) for normal use.
B3: ="Model running: "&Inputs!$D$23 -> Model running: Prahladnagar | Rent | Toll roasting | Specialty mix | Base case
B5: Override panel (data-table input cells)
B6: Scenario (0 = Inputs; 1 Best, 2 Base, 3 Worst) | D6: 0
B7: Configuration # from Configs sheet (0 = Inputs) | D7: 0
B8: Location # (0 = Inputs/config) | D8: 0
B9: Premises # (0 = Inputs/config; 1 Rent, 2 Own) | D9: 0
B10: Roasting route # (0 = Inputs/config; 1 Buy, 2 Toll, 3 In-house) | D10: 0
B11: Bean mix # (0 = Inputs/config; 1-4) | D11: 0
B12: Wholesale kg/month at maturity (0 = Inputs) | D12: 0
B13: Bills-per-day multiplier | D13: 1
B14: Average-bill multiplier | D14: 1
B15: Rent multiplier | D15: 1
B16: Green-coffee price multiplier | D16: 1
B17: Capex multiplier | D17: 1
... B22: Tornado side (1 low, 2 high) | D22: 0
B24: Tornado definitions (one variable at a time)
B25: Variable | C25: # | D25: Low | E25: High
B26: Bills per day | C26: 1 | D26: 0.85 | E26: 1.15
B27: Average bill value | C27: 2 | D27: 0.9 | E27: 1.1
B28: Rent | C28: 3 | D28: 0.8 | E28: 1.2
B29: Green-coffee price | C29: 4 | D29: 0.7 | E29: 1.3
B30: Capex | C30: 5 | D30: 0.85 | E30: 1.2
B31: Staff cost | C31: 6 | D31: 0.9 | E31: 1.15
B32: WACC (+/- pp) | C32: 7 | D32: -0.02 | E32: 0.02
B33: Terminal growth (abs.) | C33: 8 | D33: 0.03 | E33: 0.05
B35: Effective values used by the model
B36: Bills-per-day multiplier | C36: x | D36: =$D$13*IF(AND($D$21=1,$D$22>0),CHOOSE($D$22,$D$26,$E$26),1) -> 1
B37: Average-bill multiplier | C37: x | D37: =$D$14*IF(AND($D$21=2,$D$22>0),CHOOSE($D$22,$D$27,$E$27),1) -> 1
B38: Rent multiplier | C38: x | D38: =$D$15*IF(AND($D$21=3,$D$22>0),CHOOSE($D$22,$D$28,$E$28),1) -> 1
B39: Green-price multiplier | C39: x | D39: =$D$16*IF(AND($D$21=4,$D$22>0),CHOOSE($D$22,$D$29,$E$29),1) -> 1
B40: Capex multiplier | C40: x | D40: =$D$17*IF(AND($D$21=5,$D$22>0),CHOOSE($D$22,$D$30,$E$30),1) -> 1
B41: Staff-cost multiplier | C41: x | D41: =$D$18*IF(AND($D$21=6,$D$22>0),CHOOSE($D$22,$D$31,$E$31),1) -> 1
B42: Wholesale kg/month at maturity | C42: kg | D42: =IF($D$12>0,$D$12,Inputs!$D$57) -> 150
B43: WACC change | C43: pp | D43: =$D$19+IF(AND($D$21=7,$D$22>0),CHOOSE($D$22,$D$32,$E$32),0) -> 0
B44: Terminal growth | C44: % | D44: =IF(AND($D$21=8,$D$22>0),CHOOSE($D$22,$D$33,$E$33),IF($D$20>0,$D$20,Inputs!$D$159)) -> 0.04
B46: T1. Scenario analysis (Best / Base / Worst) for the active configuration
B47: Scenario | D47: NPV ₹ lakh | E47: Project IRR | F47: Equity IRR | G47: Equity NPV ₹ lakh | H47: Payback | I47: Disc. payback | J47: Capital need ₹ lakh | K47: Y3 revenue ₹ lakh | L47: Y3 EBITDA margin | M47: Break-even bills/day | N47: Peak cash credit ₹ lakh
B48: Current model value → | D48: =DCF!$D$61 -> 89.598107 | E48: =DCF!$D$64 -> 0.28636431 | F48: =DCF!$D$68 -> 0.3293081 | G48: =DCF!$D$69 -> 65.839478 | H48: =DCF!$D$76 -> 4.7237112 | I48: =DCF!$D$77 -> 8.1954564 | J48: =DCF!$D$80 -> 101.228 | K48: =DCF!$D$84 -> 177.8112 | L48: =DCF!$D$86 -> 0.18943623 | M48: =DCF!$D$89 -> 95.968282 | N48: =DCF!$D$97 -> 0
...

Sheet Configs
B1: Configurations compared
B2: Edit the blue cells to define your own combinations. Results come from data table T4 on the Scenarios sheet (active scenario).
B3: ="Model running: "&Inputs!$D$23 -> Model running: Prahladnagar | Rent | Toll roasting | Specialty mix | Base case
B5: # | C5: Name | D5: Location | E5: Premises | F5: Roasting | G5: Mix | I5: NPV ₹ lakh | J5: Project IRR | K5: Equity IRR | L5: Payback | M5: Capital ₹ lakh | N5: Y3 EBITDA % | O5: Break-even bills | P5: Rank (NPV)
B6: 1 | C6: PN-R-Buy | D6: Prahladnagar | E6: Rent | F6: Buy roasted | G6: Specialty | I6: =Scenarios!$D$100 -> 0 | J6: =Scenarios!$E$100 -> 0 | K6: =Scenarios!$F$100 -> 0 | L6: =Scenarios!$G$100 -> 0 | M6: =Scenarios!$H$100 -> 0 | N6: =Scenarios!$L$100 -> 0 | O6: =Scenarios!$M$100 -> 0 | P6: =RANK(I6,$I$6:$I$25) -> 1
B7: 2 | C7: PN-R-Toll | D7: Prahladnagar | E7: Rent | F7: Toll roasting | G7: Specialty | I7: =Scenarios!$D$101 -> 0 | J7: =Scenarios!$E$101 -> 0 | K7: =Scenarios!$F$101 -> 0 | L7: =Scenarios!$G$101 -> 0 | M7: =Scenarios!$H$101 -> 0 | N7: =Scenarios!$L$101 -> 0 | O7: =Scenarios!$M$101 -> 0 | P7: =RANK(I7,$I$6:$I$25) -> 1
B8: 3 | C8: PN-R-InH | D8: Prahladnagar | E8: Rent | F8: In-house roastery | G8: Specialty | I8: =Scenarios!$D$102 -> 0 | J8: =Scenarios!$E$102 -> 0 | K8: =Scenarios!$F$102 -> 0 | L8: =Scenarios!$G$102 -> 0 | M8: =Scenarios!$H$102 -> 0 | N8: =Scenarios!$L$102 -> 0 | O8: =Scenarios!$M$102 -> 0 | P8: =RANK(I8,$I$6:$I$25) -> 1
B9: 4 | C9: PN-O-Toll | D9: Prahladnagar | E9: Own | F9: Toll roasting | G9: Specialty | I9: =Scenarios!$D$103 -> 0 | J9: =Scenarios!$E$103 -> 0 | K9: =Scenarios!$F$103 -> 0 | L9: =Scenarios!$G$103 -> 0 | M9: =Scenarios!$H$103 -> 0 | N9: =Scenarios!$L$103 -> 0 | O9: =Scenarios!$M$103 -> 0 | P9: =RANK(I9,$I$6:$I$25) -> 1
B10: 5 | C10: PN-R-Toll-Val | D10: Prahladnagar | E10: Rent | F10: Toll roasting | G10: Value | I10: =Scenarios!$D$104 -> 0 | J10: =Scenarios!$E$104 -> 0 | K10: =Scenarios!$F$104 -> 0 | L10: =Scenarios!$G$104 -> 0 | M10: =Scenarios!$H$104 -> 0 | N10: =Scenarios!$L$104 -> 0 | O10: =Scenarios!$M$104 -> 0 | P10: =RANK(I10,$I$6:$I$25) -> 1
B11: 6 | C11: PN-R-Toll-Prm | D11: Prahladnagar | E11: Rent | F11: Toll roasting | G11: Premium | I11: =Scenarios!$D$105 -> 0 | J11: =Scenarios!$E$105 -> 0 | K11: =Scenarios!$F$105 -> 0 | L11: =Scenarios!$G$105 -> 0 | M11: =Scenarios!$H$105 -> 0 | N11: =Scenarios!$L$105 -> 0 | O11: =Scenarios!$M$105 -> 0 | P11: =RANK(I11,$I$6:$I$25) -> 1
B12: 7 | C12: PN-R-Toll-Cus | D12: Prahladnagar | E12: Rent | F12: Toll roasting | G12: Custom | I12: =Scenarios!$D$106 -> 0 | J12: =Scenarios!$E$106 -> 0 | K12: =Scenarios!$F$106 -> 0 | L12: =Scenarios!$G$106 -> 0 | M12: =Scenarios!$H$106 -> 0 | N12: =Scenarios!$L$106 -> 0 | O12: =Scenarios!$M$106 -> 0 | P12: =RANK(I12,$I$6:$I$25) -> 1
B13: 8 | C13: SBR-R-Buy | D13: Sindhu Bhavan Road | E13: Rent | F13: Buy roasted | G13: Specialty | I13: =Scenarios!$D$107 -> 0 | J13: =Scenarios!$E$107 -> 0 | K13: =Scenarios!$F$107 -> 0 | L13: =Scenarios!$G$107 -> 0 | M13: =Scenarios!$H$107 -> 0 | N13: =Scenarios!$L$107 -> 0 | O13: =Scenarios!$M$107 -> 0 | P13: =RANK(I13,$I$6:$I$25) -> 1
B14: 9 | C14: SBR-R-Toll | D14: Sindhu Bhavan Road | E14: Rent | F14: Toll roasting | G14: Specialty | I14: =Scenarios!$D$108 -> 0 | J14: =Scenarios!$E$108 -> 0 | K14: =Scenarios!$F$108 -> 0 | L14: =Scenarios!$G$108 -> 0 | M14: =Scenarios!$H$108 -> 0 | N14: =Scenarios!$L$108 -> 0 | O14: =Scenarios!$M$108 -> 0 | P14: =RANK(I14,$I$6:$I$25) -> 1
B15: 10 | C15: SBR-R-InH | D15: Sindhu Bhavan Road | E15: Rent | F15: In-house roastery | G15: Specialty | I15: =Scenarios!$D$109 -> 0 | J15: =Scenarios!$E$109 -> 0 | K15: =Scenarios!$F$109 -> 0 | L15: =Scenarios!$G$109 -> 0 | M15: =Scenarios!$H$109 -> 0 | N15: =Scenarios!$L$109 -> 0 | O15: =Scenarios!$M$109 -> 0 | P15: =RANK(I15,$I$6:$I$25) -> 1
B16: 11 | C16: SBR-O-Toll | D16: Sindhu Bhavan Road | E16: Own | F16: Toll roasting | G16: Specialty | I16: =Scenarios!$D$110 -> 0 | J16: =Scenarios!$E$110 -> 0 | K16: =Scenarios!$F$110 -> 0 | L16: =Scenarios!$G$110 -> 0 | M16: =Scenarios!$H$110 -> 0 | N16: =Scenarios!$L$110 -> 0 | O16: =Scenarios!$M$110 -> 0 | P16: =RANK(I16,$I$6:$I$25) -> 1
B17: 12 | C17: SBR-R-Toll-Cus | D17: Sindhu Bhavan Road | E17: Rent | F17: Toll roasting | G17: Custom | I17: =Scenarios!$D$111 -> 0 | J17: =Scenarios!$E$111 -> 0 | K17: =Scenarios!$F$111 -> 0 | L17: =Scenarios!$G$111 -> 0 | M17: =Scenarios!$H$111 -> 0 | N17: =Scenarios!$L$111 -> 0 | O17: =Scenarios!$M$111 -> 0 | P17: =RANK(I17,$I$6:$I$25) -> 1
B18: 13 | C18: GIFT-R-Buy | D18: GIFT City | E18: Rent | F18: Buy roasted | G18: Specialty | I18: =Scenarios!$D$112 -> 0 | J18: =Scenarios!$E$112 -> 0 | K18: =Scenarios!$F$112 -> 0 | L18: =Scenarios!$G$112 -> 0 | M18: =Scenarios!$H$112 -> 0 | N18: =Scenarios!$L$112 -> 0 | O18: =Scenarios!$M$112 -> 0 | P18: =RANK(I18,$I$6:$I$25) -> 1
B19: 14 | C19: GIFT-R-Toll | D19: GIFT City | E19: Rent | F19: Toll roasting | G19: Specialty | I19: =Scenarios!$D$113 -> 0 | J19: =Scenarios!$E$113 -> 0 | K19: =Scenarios!$F$113 -> 0 | L19: =Scenarios!$G$113 -> 0 | M19: =Scenarios!$H$113 -> 0 | N19: =Scenarios!$L$113 -> 0 | O19: =Scenarios!$M$113 -> 0 | P19: =RANK(I19,$I$6:$I$25) -> 1
B20: 15 | C20: GIFT-R-InH | D20: GIFT City | E20: Rent | F20: In-house roastery | G20: Specialty | I20: =Scenarios!$D$114 -> 0 | J20: =Scenarios!$E$114 -> 0 | K20: =Scenarios!$F$114 -> 0 | L20: =Scenarios!$G$114 -> 0 | M20: =Scenarios!$H$114 -> 0 | N20: =Scenarios!$L$114 -> 0 | O20: =Scenarios!$M$114 -> 0 | P20: =RANK(I20,$I$6:$I$25) -> 1
B21: 16 | C21: GIFT-O-Toll | D21: GIFT City | E21: Own | F21: Toll roasting | G21: Specialty | I21: =Scenarios!$D$115 -> 0 | J21: =Scenarios!$E$115 -> 0 | K21: =Scenarios!$F$115 -> 0 | L21: =Scenarios!$G$115 -> 0 | M21: =Scenarios!$H$115 -> 0 | N21: =Scenarios!$L$115 -> 0 | O21: =Scenarios!$M$115 -> 0 | P21: =RANK(I21,$I$6:$I$25) -> 1
